Workbook
Name AbodeFlag: '2441'!$R$60
Name Additional_Income: 'Sch. 1'!$AC$43
Name AdditionalCTC: '8812'!$AS$80
Name Address: '1040'!$B$14
Name Adj_Gross_Inc: '1040'!$AC$47
Name AdjustToIncome: 'Sch. 1'!$AC$86
Name AgPMT_Disaster: '1099-G'!$I$31
Name AgPMT_Other: '1099-G'!$I$32
Name Alaska: '1040'!$BC$7
Name AlimonyPaid: 'Sch. 1'!$AC$56
Name AlimonyRcvd: 'Sch. 1'!$AC$12
Name AltMinTaxInc: '6251'!$M$38
Name AMT: '6251'!$R$62
Name AMTExemption: '6251'!$AC$169
Name AMTExemptionFlag: '6251'!$AH$70
Name AO_Credit: '8863'!$AE$33
Name AOC_1: '8863'!$AE$111
Name AOC_2: '8863'!$AE$170
Name AOC_3: '8863'!$AE$229
Name AOC_4: '8863'!$AE$288
Name Apt_No.: '1040'!$W$14
Name ArcherMSADeduct: 'Sch. 1'!$AC$62
Name BadBirthdate_Spouse: '1040'!$AZ$122
Name BadBirthdate_Yours: '1040'!$AZ$102
Name BadDeathDate: '1040'!$BG$121
Name BASE_A1: 'Tax Table'!$U$7
Name BASE_A2: 'Tax Table'!$U$8
Name BASE_A3: 'Tax Table'!$U$9
Name BASE_A4: 'Tax Table'!$U$10
Name BASE_A5: 'Tax Table'!$U$11
Name BASE_A6: 'Tax Table'!$U$12
Name BASE_A7: 'Tax Table'!$U$13
Name BASE_B1: 'Tax Table'!$U$17
Name BASE_B2: 'Tax Table'!$U$18
Name BASE_B3: 'Tax Table'!$U$19
Name BASE_B4: 'Tax Table'!$U$20
Name BASE_B5: 'Tax Table'!$U$21
Name BASE_B6: 'Tax Table'!$U$22
Name BASE_B7: 'Tax Table'!$U$23
Name BASE_C1: 'Tax Table'!$U$27
Name BASE_C2: 'Tax Table'!$U$28
Name BASE_C3: 'Tax Table'!$U$29
Name BASE_C4: 'Tax Table'!$U$30
Name BASE_C5: 'Tax Table'!$U$31
Name BASE_C6: 'Tax Table'!$U$32
Name BASE_C7: 'Tax Table'!$U$33
Name BASE_D1: 'Tax Table'!$U$38
Name BASE_D2: 'Tax Table'!$U$39
Name BASE_D3: 'Tax Table'!$U$40
Name BASE_D4: 'Tax Table'!$U$41
Name BASE_D5: 'Tax Table'!$U$42
Name BASE_D6: 'Tax Table'!$U$43
Name BASE_D7: 'Tax Table'!$U$44
Name BeginningOfTaxYear: '1040'!$AX$2
Name Birthday_Needed: '1040'!$AX$113
Name BOTT_A1: 'Tax Table'!$T$7
Name BOTT_A2: 'Tax Table'!$T$8
Name BOTT_A3: 'Tax Table'!$T$9
Name BOTT_A4: 'Tax Table'!$T$10
Name BOTT_A5: 'Tax Table'!$T$11

Sheet Coversheet
D1: Revision Date/Time: | E1: =RevDateTime -> 46003.399
B2: -- DISCLAIMER -- These spreadsheets are provided "as is", with no warranty of any kind, expressed or implied, and in no event will Glenn Reeves be liable for direct, indirect, incidental, or consequential damages resulting from the use of any of these spreadsheets. Glenn Reeves specifically disclaims the role of tax adviser. These spreadsheets attempt to perform the mechanics of tax preparation in accordance with IRS forms and instructions. The user must assume responsibility as to the correctness and appropriateness of any and all amounts entered and results produced.
B12: No password is needed. If you find a data entry cell to be protected, it is because it is a calculated value using input from another location in the spreadsheet. Read the instructions for that line to determine where the values are derived. However, for most calculated cells, a manual override cell is provided if you need to override the calculated value. After a while, you will figure out that the spreadsheet is completely functional without needing to unprotect it.
B22: Errors If you find an error, first check the revision date/time above against the revision number of the latest spreadsheet to be published at:
E24: https://sites.google.com/view/incometaxspreadsheet/home/changes
C25: If you find you're using an earlier version, review the changes made since your version
C26: to determine if the problem you've encountered has has already been fixed.
C27: If so, please download the latest version and begin again. (There is no simple way to migrate...)
C28: If you cannot determine (or you're not sure) as to whether or not the problem(s) you've found
C29: has been corrected, please do your fellow taxpayers a favor by reporting the problem to:
E30: incometaxspreadsheet@gmail.com
B33: SUMMARY
B34: Adjusted Gross Income | E34: =Adj_Gross_Inc -> 0 | G34: Form 1040, Line 11 | M34: Single | N34: =IF(Taxable_Inc="","---",IF(Taxable_Inc<BOTT_A2,TEXT(RATE_A1,"0%"),IF(Taxable_Inc<BOTT_A3,TEXT(RATE_A2,"0%"),IF(Taxable_Inc<BOTT_A4,TEXT(RATE_A3,"0%"),IF(Taxable_Inc<BOTT_A5,TEXT(RATE_A4,"0%"),IF(Taxable_Inc<BOTT_A6,TEXT(RATE_A5,"0%"),IF(Taxable_Inc<BOTT_A7,TEXT(RATE_A6,"0%"),TEXT(RATE_A7,"0.0%")))))))) -> 10%
B35: Total Deductions | E35: =TotalDeductions -> 0 | G35: Form 1040, Line 14
B36: Taxable Income | E36: =Taxable_Inc -> 0 | G36: Form 1040, Line 15 | M36: MFJ or QW | N36: =IF(Taxable_Inc="","---",IF(Taxable_Inc<BOTT_B2,TEXT(RATE_B1,"0%"),IF(Taxable_Inc<BOTT_B3,TEXT(RATE_B2,"0%"),IF(Taxable_Inc<BOTT_B4,TEXT(RATE_B3,"0%"),IF(Taxable_Inc<BOTT_B5,TEXT(RATE_B4,"0%"),IF(Taxable_Inc<BOTT_B6,TEXT(RATE_B5,"0%"),IF(Taxable_Inc<BOTT_B7,TEXT(RATE_B6,"0%"),TEXT(RATE_B7,"0.0%")))))))) -> 10%
B37: Total Tax | E37: =Tot_Tax -> 0 | G37: Form 1040, Line 24 | M37: MFS | N37: =IF(Taxable_Inc="","---",IF(Taxable_Inc<BOTT_C2,TEXT(RATE_C1,"0%"),IF(Taxable_Inc<BOTT_C3,TEXT(RATE_C2,"0%"),IF(Taxable_Inc<BOTT_C4,TEXT(RATE_C3,"0%"),IF(Taxable_Inc<BOTT_C5,TEXT(RATE_C4,"0%"),IF(Taxable_Inc<BOTT_C6,TEXT(RATE_C5,"0%"),IF(Taxable_Inc<BOTT_C7,TEXT(RATE_C6,"0%"),TEXT(RATE_C7,"0.0%")))))))) -> 10%
B38: Total Payments/Credits | E38: =Tot_Payments -> 0 | G38: Form 1040, Line 33 | M38: HOH | N38: =IF(Taxable_Inc="","---",IF(Taxable_Inc<BOTT_D2,TEXT(RATE_D1,"0%"),IF(Taxable_Inc<BOTT_D3,TEXT(RATE_D2,"0%"),IF(Taxable_Inc<BOTT_D4,TEXT(RATE_D3,"0%"),IF(Taxable_Inc<BOTT_D5,TEXT(RATE_D4,"0%"),IF(Taxable_Inc<BOTT_D6,TEXT(RATE_D5,"0%"),IF(Taxable_Inc<BOTT_D7,TEXT(RATE_D6,"0%"),TEXT(RATE_D7,"0.0%")))))))) -> 10%
B39: =IF(Overpaid>0,"Amount You Overpaid",IF(AND(E39<>"",E39>0),"Amount You Underpaid","")) | E39: =IF(Overpaid>0,Overpaid,IF(SUM(Tot_Tax,-Tot_Payments)>0,SUM(Tot_Tax,-Tot_Payments),"")) | G39: =IF(Overpaid>0,"Form 1040, Line 34","")
B40: =IF(TaxPenalty>0,"Penalty/Interest","") | E40: =IF(TaxPenalty>0,TaxPenalty,"") | G40: =IF(TaxPenalty>0,"Form 1040, Line 38","")
B41: =IF(Overpaid>0,"Amount To be Refunded","Amount You Owe") -> Amount You Owe | E41: =IF(Overpaid>0,Overpaid,You_Owe) -> 0 | G41: =IF(Overpaid>0,"Form 1040, Line 35a","Form 1040, Line 37") -> Form 1040, Line 37
B43: Tax Bracket | E43: =IF(File_Single<>"",N34,IF(OR(File_Marr_Joint<>"",File_Qual_Widow<>""),N36,IF(File_Marr_Sep<>"",N37,IF(File_Head<>"",N38,"---")))) -> ---
B47: This spreadsheet is free. However, if you would like to show your appreciation, you may make a contribution by clicking one of the following links and sending money as indicated.
C52: PayPal | E52: Zelle (App)
C53: https://paypal.me/incometaxspreadsheet | E53: https://www.zellepay.com/
C54: (Send to: IncomeTaxSpreadsheet@gmail.com ) | E54: (Send to: IncomeTaxSpreadsheet@gmail.com )
C56: Google Pay | E56: Popmoney
C57: https://pay.google.com/payments/ | E57: https://www.popmoney.com/
C58: (Send to: IncomeTaxSpreadsheet@gmail.com ) | E58: (Send to: IncomeTaxSpreadsheet@gmail.com )
C60: US Mail:
C61: Glenn Reeves
C62: (Tax Calculator)
C63: 4802 N 124th Ct
C64: Kansas City, KS 66109-3809
D66: Thank you for using my spreadsheet and for any money you decide to send!

Sheet Table of Contents
C2: Sheet Name (with hyperlink)
D3: Federal Income Tax Spreadsheet | M3: Updated
D4: Table of Contents | H4: Draft IRS | I4: Updated | J4: Final IRS | K4: Draft IRS | L4: Final IRS | M4: Final
D5: ="© Glenn Reeves, "&TaxYear+1 -> © Glenn Reeves, 2022 | G5: Form | H5: Form | I5: Draft Form | J5: Form | K5: Instruction | L5: Instruction
D6: Title / Description | G6: Last checked | H6: 44498
C7: Coversheet | D7: Possible tax return coversheet which includes a disclaimer, important notes, and a summary.
C8: Table of Contents | D8: Table of contents with links to the sheets included in this spreadsheet.
C9: Instructions | D9: Important notes, general notes, and instructions to help you get started.
C10: W-2s | D10: Form W-2, Wage and Tax Statement | F10: 1 | G10: =C10 -> W-2s
C11: 1099-INT | D11: Form 1099-INT, Interest Income | F11: 2 | G11: =C11 -> 1099-INT
C12: 1099-DIV | D12: Form 1099-DIV, Dividend Income | F12: 3 | G12: =C12 -> 1099-DIV
C13: 1099-G | D13: Form 1099-G, Certain Government Payments | F13: 4 | G13: =C13 -> 1099-G
C14: 1099-MISC | D14: Form 1099-MISC, Miscellaneous Income (Way too complicated -- included for information) | F14: 5 | G14: =C14 -> 1099-MISC
C15: 1099-R | D15: Form 1099-R, Distributions From Pensions, Annuities, Retirement or Profit-Sharing Plans, IRAs, Insurance Contracts, etc. | F15: 6 | G15: =C15 -> 1099-R
C16: SSA-1099 | D16: Form SSA-1099, Social Security Benefit Statement and IRS Notice 703, To See If Your Social Security Benefits May Be Taxable | F16: 7 | G16: =C16 -> SSA-1099
C17: 1040 | D17: Form 1040, U.S. Individual Income Tax Return | F17: 8 | G17: =C17 -> 1040 | H17: 44398 | I17: 44500 | J17: 44539 | K17: 44237 | L17: 44552 | M17: 44567
C18: Sch. 1 | D18: Schedule 1, Additional Income and Adjustments to Income | F18: 9 | G18: =C18 -> Sch. 1 | H18: 44398 | J18: 44533 | M18: 44568
C19: Sch. 1, Line 1 (SALT) | D19: State and Local Income Tax Refund Worksheet — Line 1 | F19: 17 | G19: =C19 -> Sch. 1, Line 1 (SALT) | M19: 44568
C20: Sch. 1 Line 20 (IRA) | D20: IRA Deduction Worksheet — Schedule 1, Line 20 | F20: 22 | G20: =C20 -> Sch. 1 Line 20 (IRA) | M20: 44578
C21: Sch. 1 Line 21 (Stu Loan) | D21: Student Loan Interest Deduction Worksheet — Schedule 1, Line 21 | F21: 23 | G21: =C21 -> Sch. 1 Line 21 (Stu Loan) | M21: 44578
C22: Sch. 2 | D22: Schedule 2, Additional Taxes | F22: 11 | G22: =C22 -> Sch. 2 | H22: 44398 | J22: 44533 | M22: 44568
C23: Sch. 3 | D23: Schedule 3, Nonrefundable Credits | F23: 12 | G23: =C23 -> Sch. 3 | H23: 44495 | I23: 44500 | J23: 44533 | M23: 44568
C24: Earned Inc WS | D24: Earned Income Worksheet — Used as input to Line 9 (SD Depnts), Line 13a (CTC), & Form 8812. | F24: 13 | G24: =C24 -> Earned Inc WS
C25: Lines 5ab (Simplified Meth WS) | D25: Simplified Method Worksheet—Lines 5a and 5b -- to determine taxable amount of retirement pension or annuity. | F25: 14 | G25: =C25 -> Lines 5ab (Simplified Meth WS) | M25: 44578
C26: Line 6ab (SS Bene) | D26: Social Security Benefits Worksheet – Lines 6a and 6b -- to determine taxable amount of Social Security benefits. | F26: 15 | G26: =C26 -> Line 6ab (SS Bene) | M26: 44571
C27: Line 12 (SD Depnts) | D27: Standard Deduction Worksheet for Dependents — Line 12 | F27: 16 | G27: =C27 -> Line 12 (SD Depnts) | M27: 44571
C28: Line 16 (QDCG Tax) | D28: Qualified Dividends and Capital Gain Tax Worksheet—Line 12a | F28: 18 | G28: =C28 -> Line 16 (QDCG Tax) | M28: 44571
C29: Line 27 (EIC) | D29: Line 27 — Earned Income Credit Worksheet — Spreadsheet provides assistance in completing this. | F29: 20 | G29: =C29 -> Line 27 (EIC)
C30: Line 30 (Rebate Credit) | D30: Recovery Rebate Credit Worksheet—Line 30 | F30: 21 | G30: =C30 -> Line 30 (Rebate Credit) | M30: 44575
C31: Sch. A | D31: Schedule A, Itemized Deductions | F31: 24 | G31: =C31 -> Sch. A | H31: 44426 | J31: 44550 | L31: 44566 | M31: 44578
C32: Sch. B | D32: Schedule B, Interest and Ordinary Dividends | F32: 25 | G32: =C32 -> Sch. B | H32: 44369 | J32: 44503 | K32: 44399 | L32: 44539 | M32: 44578
C33: Sch. C | D33: Schedule C, Profit or Loss from Business (Two Schedule C's are included) | F33: 26 | G33: =C33 -> Sch. C | H33: 44364 | J33: 44494 | K33: 44489 | L33: 44552 | M33: 44579
C34: Sch. D | D34: Schedule D, Capital Gains and Losses | F34: 27 | G34: =C34 -> Sch. D | H34: 44426 | J34: 44540 | K34: 44489 | L34: 44544 | M34: 44579
C35: Sch. D WS | D35: Schedule D Worksheets - Capital Loss Carryover Worksheet—Schedule D, Lines 6 and 14 - 28% Rate Gain Worksheet—Schedule D, Line 18 - Schedule D Tax Worksheet | F35: 28 | G35: =C35 -> Sch. D WS | M35: 44581
C36: Sch. E | D36: Schedule E, Supplemental Income and Loss (2 forms) | F36: 29 | G36: =C36 -> Sch. E | H36: 44364 | J36: 44494 | K36: 44467 | L36: 44545 | M36: 44498 | N36: Check against instructions.
C37: Sch. E (2) | D37: Schedule E, Supplemental Income and Loss (2 forms) | F37: 29 | G37: =C37 -> Sch. E (2) | H37: 44364 | J37: 44494 | K37: 44467 | L37: 44545 | M37: 44498 | N37: Check against instructions.
C38: Sch. F | D38: Schedule F, Profit or Loss from Farming | F38: 30 | G38: =C38 -> Sch. F | H38: 44497 | J38: 44551 | L38: 44553 | M38: 44575
C39: Sch. R | D39: Schedule R, Credit for the Elderly or the Disabled | F39: 31 | G39: =C39 -> Sch. R | H39: 44400 | J39: 44494 | K39: 44446 | L39: 44494 | M39: 44576
C40: Sch. SE | D40: Schedule SE, Self-Employement Tax (Two Schedule SE's are included) | F40: 32 | G40: =C40 -> Sch. SE | H40: 44363 | J40: 44494 | L40: 44536 | M40: 44499 | N40: Check against instructions.
C41: 1116 | D41: Form 1116, Foreign Tax Credit | F41: 33 | G41: =C41 -> 1116 | H41: 44454 | J41: 44544 | M41: 44576
...

Sheet Instructions
A2: Excel1040 -- Income Tax Spreadsheet
A3: Instructions for Use
B5: IMPORTANT NOTES:
B6: 1. | C6: The purpose of this spreadsheet is to help U.S. taxpayers calculate their own federal income tax returns.
C7: The spreadsheet attempts to perform the mechanics of tax preparation (i.e. 'do the math') in accordance
C8: with IRS forms and instructions.
B10: 2. | C10: This spreadsheet is designed for taxpayers who are capable of preparing their own federal income tax returns.
C11: Users of this spreadsheet must know what information needs to be entered and where to enter it.
C12: Users of this spreadsheet must also be sufficiently familiar with the IRS forms and instructions that apply to
C13: their tax return in order to detect and correct any and all user and spreadsheet errors that might occur.
C14: Although some error checking is included, this spreadsheet will not prevent you from making mistakes.
B16: 3. | C16: The user must assume full responsibility as to the correctness and appropriateness of any and all amounts
C17: entered and results produced. Be sure to use current copies of actual IRS forms and instructions when
C18: validating the spreadsheet's results. IRS forms and instructions: | I18: https://www.irs.gov/downloads/irs-pdf
B20: 4. | C20: It is vitally important that all spreadsheet users promptly report any error(s) they find so that the spreadsheet
C21: can be corrected. | F21: Report errors to: | G21: incometaxspreadsheet@gmail.com
B23: GENERAL NOTES:
B24: 1. | C24: Unprotected data entry cells have a light blue fill color.
C25: Cells containing calculated amounts are usually protected and have a darker blue fill color.
C26: Form and worksheet areas are protected. However, users are able to adjust printing properties.
B28: 2. | C28: "Manual override" cells are available for many calculated cells. The use of override cells is discouraged
C29: because manual overrides can defeat the spreadsheet's automatic updating feature. If you are having
C30: to use a manual override because of a spreadsheet error, be sure to report the error as soon as possible.
C32: NOTE: To clear data from an override cell, highlight it and then press the <Delete> key.
C33: Do not press the <space> bar because, although it is invisible, the <space> character is treated the
C34: same as any visible character.
B36: 3. | C36: To check a checkbox, simply type an 'X' (any character will work) in the box and press <Enter>.
C38: NOTE: To clear an 'X' from an checkbox, highlight it and then press the <Delete> key.
C39: Do not press the <space> bar because, although it is invisible, the <space> character is treated the
C40: same as any visible character.
B42: 4. | C42: Prior to printing, to remove colors from all forms and worksheets, place an 'X' in Cell AK2 on the '1040' sheet.
C43: Likewise, to remove social security numbers from all forms and worksheets, place an "X" in Cell AK3 on the '1040' sheet.
B45: 5. | C45: If using copy/paste to copy information from another source, be sure to paste using 'Paste-Values'.
C46: Otherwise, cell properties could be inadvertently changed. (e.g. A normally unprotected cell could become
C47: protected.)
B49: 6. | C49: DO NOT DELETE UNUSED SHEETS. This spreadsheet employs references and links that tie one sheet to
C50: one or more other sheets which ultimately feed to the Form 1040. Deleting any sheet will most likely cause the
C51: spreadsheet to completely stop functioning.
B53: 7. | C53: On Form 1040, to save time, it's generally okay to enter alternate information (e.g. SSN = 111-22-3333).
C54: Be aware, to perform an accurate tax calculation, the spreadsheet will need reasonably accurate birthdate,
...

Sheet W-2s
B1: Information from Form W-2, Wage and Tax Statement | F1: Maximum SS Tax Earnings: | G1: 142800 | H1: SS Tax Rate: | I1: 0.062 | K1: Max. SS Tax: | L1: =MaxSSTaxEarnings*SSTaxRate -> 8853.6 | M1: per person | O1: Notes
B2: =IF(Name_1st_Yours="","Enter your name on the"&CHAR(10)&"sheet labeled '1040'",NameYours) -> Enter your name on the sheet labeled '1040' | C2: Employer #1 | D2: Employer #2 | E2: Employer #3 | F2: Employer #4 | G2: Employer #5 | H2: Employer #6 | I2: Total | J2: Excess | L2: Used at: | O2: Date
A3: 1 | B3: Wages, tips, other compensation | I3: =SUM(ROUND(C3,0),ROUND(D3,0),ROUND(E3,0),ROUND(F3,0),ROUND(G3,0),ROUND(H3,0)) -> 0 | N3: =130000 -> 130000
A4: 2 | B4: Federal income tax withheld | I4: =SUM(ROUND(C4,0),ROUND(D4,0),ROUND(E4,0),ROUND(F4,0),ROUND(G4,0),ROUND(H4,0)) -> 0 | N4: =0.13*N3 -> 16900
A5: 3 | B5: Social security wages | I5: =SUM(ROUND(C5,0),ROUND(D5,0),ROUND(E5,0),ROUND(F5,0),ROUND(G5,0),ROUND(H5,0)) -> 0 | L5: Sch. SE, Line 8a | N5: =MIN(N3,MaxSSTaxEarnings) -> 130000
A6: 4 | B6: Social security tax withheld | I6: =SUM(C6:H6) -> 0 | J6: =IF(EmployerCountYou<2,0,IF(AND(EmployerCountYou>1,SUM(I6,-MaxSSTax)>0),SUM(I6,-MaxSSTax),0)) -> 0 | N6: =MIN(SSTaxRate*N3,MaxSSTax) -> 8060
A7: 5 | B7: Medicare wages and tips | I7: =SUM(ROUND(C7,0),ROUND(D7,0),ROUND(E7,0),ROUND(F7,0),ROUND(G7,0),ROUND(H7,0)) -> 0 | N7: =N3 -> 130000
A8: 6 | B8: Medicare tax withheld | I8: =SUM(ROUND(C8,0),ROUND(D8,0),ROUND(E8,0),ROUND(F8,0),ROUND(G8,0),ROUND(H8,0)) -> 0 | L8: Only bolded amounts are used in this spreadsheet. | N8: =0.0145*N7 -> 1885
A9: 7 | B9: Social Security Tips | I9: =SUM(ROUND(C9,0),ROUND(D9,0),ROUND(E9,0),ROUND(F9,0),ROUND(G9,0),ROUND(H9,0)) -> 0 | L9: Sch. SE, Line 8a
A10: 8 | B10: Allocated Tips | I10: =SUM(ROUND(C10,0),ROUND(D10,0),ROUND(E10,0),ROUND(F10,0),ROUND(G10,0),ROUND(H10,0)) -> 0
A11: 10 | B11: Dependent Care Benefits | I11: =SUM(ROUND(C11,0),ROUND(D11,0),ROUND(E11,0),ROUND(F11,0),ROUND(G11,0),ROUND(H11,0)) -> 0
A12: 11 | B12: Nonqualified plans | I12: =SUM(ROUND(C12,0),ROUND(D12,0),ROUND(E12,0),ROUND(F12,0),ROUND(G12,0),ROUND(H12,0)) -> 0
A13: 12a | B13: See instructions for box 12 | I13: =SUM(ROUND(C13,0),ROUND(D13,0),ROUND(E13,0),ROUND(F13,0),ROUND(G13,0),ROUND(H13,0)) -> 0
A14: 12b | I14: =SUM(ROUND(C14,0),ROUND(D14,0),ROUND(E14,0),ROUND(F14,0),ROUND(G14,0),ROUND(H14,0)) -> 0
A15: 12c | I15: =SUM(ROUND(C15,0),ROUND(D15,0),ROUND(E15,0),ROUND(F15,0),ROUND(G15,0),ROUND(H15,0)) -> 0
A16: 12d | I16: =SUM(ROUND(C16,0),ROUND(D16,0),ROUND(E16,0),ROUND(F16,0),ROUND(G16,0),ROUND(H16,0)) -> 0
A17: 13 | B17: Stat Emp / Retire / 3rd Party Sick | I17: =SUM(ROUND(C17,0),ROUND(D17,0),ROUND(E17,0),ROUND(F17,0),ROUND(G17,0),ROUND(H17,0)) -> 0
A18: 14 | B18: Other | I18: =SUM(ROUND(C18,0),ROUND(D18,0),ROUND(E18,0),ROUND(F18,0),ROUND(G18,0),ROUND(H18,0)) -> 0
A19: 14 | B19: Railroad retire (RRTA) compensation | I19: =SUM(ROUND(C19,0),ROUND(D19,0),ROUND(E19,0),ROUND(F19,0),ROUND(G19,0),ROUND(H19,0)) -> 0
A20: 14 | B20: RRTA medicare tax withheld (see Form CT-2) | I20: =SUM(ROUND(C20,0),ROUND(D20,0),ROUND(E20,0),ROUND(F20,0),ROUND(G20,0),ROUND(H20,0)) -> 0
A21: 16 | B21: State wages, tips, etc. | I21: =SUM(ROUND(C21,0),ROUND(D21,0),ROUND(E21,0),ROUND(F21,0),ROUND(G21,0),ROUND(H21,0)) -> 0
A22: 17 | B22: State income tax | I22: =SUM(ROUND(C22,0),ROUND(D22,0),ROUND(E22,0),ROUND(F22,0),ROUND(G22,0),ROUND(H22,0)) -> 0 | N22: =0.05*N3 -> 6500
A23: 18 | B23: Local wages, tips, etc. | I23: =SUM(ROUND(C23,0),ROUND(D23,0),ROUND(E23,0),ROUND(F23,0),ROUND(G23,0),ROUND(H23,0)) -> 0
A24: 19 | B24: Local income tax | I24: =SUM(ROUND(C24,0),ROUND(D24,0),ROUND(E24,0),ROUND(F24,0),ROUND(G24,0),ROUND(H24,0)) -> 0
B25: Employer count (You) | C25: =IF(AND(C6<>"",C6<>0),1,0) -> 0 | D25: =IF(AND(D6<>"",D6<>0),1,0) -> 0 | E25: =IF(AND(E6<>"",E6<>0),1,0) -> 0 | F25: =IF(AND(F6<>"",F6<>0),1,0) -> 0 | G25: =IF(AND(G6<>"",G6<>0),1,0) -> 0 | H25: =IF(AND(H6<>"",H6<>0),1,0) -> 0 | I25: =SUM(C25:H25) -> 0
B26: ="Medicare wages and tip > "&TEXT('8959'!$H$24,"$0,000") -> Medicare wages and tip > $200,000 | C26: =IF(C7>'8959'!$H$24,TRUE,FALSE) -> FALSE | D26: =IF(D7>'8959'!$H$24,TRUE,FALSE) -> FALSE | E26: =IF(E7>'8959'!$H$24,TRUE,FALSE) -> FALSE | F26: =IF(F7>'8959'!$H$24,TRUE,FALSE) -> FALSE | G26: =IF(G7>'8959'!$H$24,TRUE,FALSE) -> FALSE | H26: =IF(H7>'8959'!$H$24,TRUE,FALSE) -> FALSE
B27: ="RRTA > "&TEXT('8959'!$H$24,"$0,000") -> RRTA > $200,000 | C27: =IF(C19>'8959'!$H$24,TRUE,FALSE) -> FALSE | D27: =IF(D19>'8959'!$H$24,TRUE,FALSE) -> FALSE | E27: =IF(E19>'8959'!$H$24,TRUE,FALSE) -> FALSE | F27: =IF(F19>'8959'!$H$24,TRUE,FALSE) -> FALSE | G27: =IF(G19>'8959'!$H$24,TRUE,FALSE) -> FALSE | H27: =IF(H19>'8959'!$H$24,TRUE,FALSE) -> FALSE
C28: =IF(AND(I6>MaxSSTax,EmployerCountYou=1),"Notify your employer that they withheld "&TEXT(SUM(I6,-MaxSSTax),"$0.00")&" too much Social Security Tax or file Form 843, Claim for Refund and Request for Abatement.","")
B29: =IF(OR(AND(C7="",C8<>""),AND(D7="",D8<>""),AND(E7="",E8<>""),AND(F7="",F8<>"")),"CAUTION: Entering an amount into Line 6 without entering an amount into Line 5 will result in a tax calculation error.","")
B30: Information from Form W-2, Wage and Tax Statement
B31: =IF(Name_1st_Sp="","Enter your spouse's name on"&CHAR(10)&"the sheet labeled '1040'",NameSpouse) -> Enter your spouse's name on the sheet labeled '1040' | C31: Employer #1 | D31: Employer #2 | E31: Employer #3 | F31: Employer #4 | G31: Employer #5 | H31: Employer #6 | I31: Total | J31: Excess | L31: Used at:
A32: 1 | B32: Wages, tips, other compensation | I32: =SUM(ROUND(C32,0),ROUND(D32,0),ROUND(E32,0),ROUND(F32,0),ROUND(G32,0),ROUND(H32,0)) -> 0
A33: 2 | B33: Federal income tax withheld | I33: =SUM(ROUND(C33,0),ROUND(D33,0),ROUND(E33,0),ROUND(F33,0),ROUND(G33,0),ROUND(H33,0)) -> 0
A34: 3 | B34: Social security wages | I34: =SUM(ROUND(C34,0),ROUND(D34,0),ROUND(E34,0),ROUND(F34,0),ROUND(G34,0),ROUND(H34,0)) -> 0 | L34: Sch. SE, Line 8a
A35: 4 | B35: Social security tax withheld | I35: =SUM(C35:H35) -> 0 | J35: =IF(EmployerCountSpouse<2,0,IF(AND(EmployerCountSpouse>1,SUM(I35,-MaxSSTax)>0),SUM(I35,-MaxSSTax),0)) -> 0
A36: 5 | B36: Medicare wages and tips | I36: =SUM(ROUND(C36,0),ROUND(D36,0),ROUND(E36,0),ROUND(F36,0),ROUND(G36,0),ROUND(H36,0)) -> 0
A37: 6 | B37: Medicare tax withheld | I37: =SUM(ROUND(C37,0),ROUND(D37,0),ROUND(E37,0),ROUND(F37,0),ROUND(G37,0),ROUND(H37,0)) -> 0 | L37: Only bolded amounts are used in this spreadsheet.
A38: 7 | B38: Social Security Tips | I38: =SUM(ROUND(C38,0),ROUND(D38,0),ROUND(E38,0),ROUND(F38,0),ROUND(G38,0),ROUND(H38,0)) -> 0 | L38: Sch. SE, Line 8a
A39: 8 | B39: Allocated Tips | I39: =SUM(ROUND(C39,0),ROUND(D39,0),ROUND(E39,0),ROUND(F39,0),ROUND(G39,0),ROUND(H39,0)) -> 0
A40: 10 | B40: Dependent Care Benefits | I40: =SUM(ROUND(C40,0),ROUND(D40,0),ROUND(E40,0),ROUND(F40,0),ROUND(G40,0),ROUND(H40,0)) -> 0
...

Sheet 1099-INT
B1: Information from Form 1099-INT, Interest Income | K1: Notes
C2: =IF(Name_1st_Yours="","Enter your name(s) on the"&CHAR(10)&"sheet lableled '1040'",IF(File_Marr_Joint<>"",NameYours&CHAR(10)&" and "&NameSpouse,NameYours)) -> Enter your name(s) on the sheet lableled '1040' | D2: Payer #1 | E2: Payer #2 | F2: Payer #3 | G2: Payer #4 | H2: Payer #5 | K2: Date:
C3: PAYER's name
C4: PAYER's Federal ID number
C5: Account number
B6: 1 | C6: Interest income | AA6: =ROUND(D6,0) -> 0 | AB6: =ROUND(E6,0) -> 0 | AC6: =ROUND(F6,0) -> 0 | AD6: =ROUND(G6,0) -> 0 | AE6: =ROUND(H6,0) -> 0
B7: 2 | C7: Early withdrawal penalty | AA7: =ROUND(D7,0) -> 0 | AB7: =ROUND(E7,0) -> 0 | AC7: =ROUND(F7,0) -> 0 | AD7: =ROUND(G7,0) -> 0 | AE7: =ROUND(H7,0) -> 0
B8: 3 | C8: Interest on U.S. Savings Bonds & Treas. Obligations | AA8: =ROUND(D8,0) -> 0 | AB8: =ROUND(E8,0) -> 0 | AC8: =ROUND(F8,0) -> 0 | AD8: =ROUND(G8,0) -> 0 | AE8: =ROUND(H8,0) -> 0
B9: 3A | C9: Include Line 3 on Schedule B, Line 1? (Y / N) | D9: N | E9: N | F9: N | G9: N | H9: N
B10: 4 | C10: Federal income tax withheld | AA10: =ROUND(D10,0) -> 0 | AB10: =ROUND(E10,0) -> 0 | AC10: =ROUND(F10,0) -> 0 | AD10: =ROUND(G10,0) -> 0 | AE10: =ROUND(H10,0) -> 0
B11: 5 | C11: Investment expenses | AA11: =ROUND(D11,0) -> 0 | AB11: =ROUND(E11,0) -> 0 | AC11: =ROUND(F11,0) -> 0 | AD11: =ROUND(G11,0) -> 0 | AE11: =ROUND(H11,0) -> 0
B12: 6 | C12: Foreign tax paid | I12: =IF(SUM(D12:H12)>0,"Check Form 1116, Foreign Tax Credit","") | AA12: =ROUND(D12,0) -> 0 | AB12: =ROUND(E12,0) -> 0 | AC12: =ROUND(F12,0) -> 0 | AD12: =ROUND(G12,0) -> 0 | AE12: =ROUND(H12,0) -> 0
B13: 7 | C13: Foreign country or U.S. possession | AA13: =ROUND(D13,0) -> 0 | AB13: =ROUND(E13,0) -> 0 | AC13: =ROUND(F13,0) -> 0 | AD13: =ROUND(G13,0) -> 0 | AE13: =ROUND(H13,0) -> 0
B14: 8 | C14: Tax-exempt interest | AA14: =ROUND(D14,0) -> 0 | AB14: =ROUND(E14,0) -> 0 | AC14: =ROUND(F14,0) -> 0 | AD14: =ROUND(G14,0) -> 0 | AE14: =ROUND(H14,0) -> 0
B15: 9 | C15: Specified private activity bond interest | AA15: =ROUND(D15,0) -> 0 | AB15: =ROUND(E15,0) -> 0 | AC15: =ROUND(F15,0) -> 0 | AD15: =ROUND(G15,0) -> 0 | AE15: =ROUND(H15,0) -> 0
B17: 10 | C17: Market discount | AA17: =ROUND(D17,0) -> 0 | AB17: =ROUND(E17,0) -> 0 | AC17: =ROUND(F17,0) -> 0 | AD17: =ROUND(G17,0) -> 0 | AE17: =ROUND(H17,0) -> 0
B18: 11 | C18: Bond premium | AA18: =ROUND(D18,0) -> 0 | AB18: =ROUND(E18,0) -> 0 | AC18: =ROUND(F18,0) -> 0 | AD18: =ROUND(G18,0) -> 0 | AE18: =ROUND(H18,0) -> 0
B19: 12 | C19: Bond premium on Treasury obligations | AA19: =ROUND(D19,0) -> 0 | AB19: =ROUND(E19,0) -> 0 | AC19: =ROUND(F19,0) -> 0 | AD19: =ROUND(G19,0) -> 0 | AE19: =ROUND(H19,0) -> 0
B20: 13 | C20: Bond premium on tax–exempt bond | AA20: =ROUND(D20,0) -> 0 | AB20: =ROUND(E20,0) -> 0 | AC20: =ROUND(F20,0) -> 0 | AD20: =ROUND(G20,0) -> 0 | AE20: =ROUND(H20,0) -> 0
B21: 14 | C21: Tax-exempt and tax credit bond CUSIP no. | AA21: =ROUND(D21,0) -> 0 | AB21: =ROUND(E21,0) -> 0 | AC21: =ROUND(F21,0) -> 0 | AD21: =ROUND(G21,0) -> 0 | AE21: =ROUND(H21,0) -> 0
B22: 15 | C22: State
B23: 17 | C23: State identification no.
B24: 17 | C24: State tax withheld | AA24: =ROUND(D24,0) -> 0 | AB24: =ROUND(E24,0) -> 0 | AC24: =ROUND(F24,0) -> 0 | AD24: =ROUND(G24,0) -> 0 | AE24: =ROUND(H24,0) -> 0
B25: Only bolded amounts are used in this spreadsheet.
D26: =IF(OR(LEFT(D9,1)="Y",LEFT(D9,1)="y"),D8,"") | E26: =IF(OR(LEFT(E9,1)="Y",LEFT(E9,1)="y"),E8,"") | F26: =IF(OR(LEFT(F9,1)="Y",LEFT(F9,1)="y"),F8,"") | G26: =IF(OR(LEFT(G9,1)="Y",LEFT(G9,1)="y"),G8,"") | H26: =IF(OR(LEFT(H9,1)="Y",LEFT(H9,1)="y"),H8,"")
D27: =IF(D3<>"",D3,"") | E27: =IF(E3<>"",E3,"") | F27: =IF(F3<>"",F3,"") | G27: =IF(G3<>"",G3,"") | H27: =IF(H3<>"",H3,"")
D28: =IF(D4<>"", " - "&D4,"") | E28: =IF(E4<>"", " - "&E4,"") | F28: =IF(F4<>"", " - "&F4,"") | G28: =IF(G4<>"", " - "&G4,"") | H28: =IF(H4<>"", " - "&H4,"")
D29: =IF(D5<>""," - "&D5,"") | E29: =IF(E5<>""," - "&E5,"") | F29: =IF(F5<>""," - "&F5,"") | G29: =IF(G5<>""," - "&G5,"") | H29: =IF(H5<>""," - "&H5,"")
D30: =D27&D28&D29 | E30: =E27&E28&E29 | F30: =F27&F28&F29 | G30: =G27&G28&G29 | H30: =H27&H28&H29
C31: =IF(Name_1st_Yours="","Enter your name(s) on the"&CHAR(10)&"sheet lableled '1040'",IF(File_Marr_Joint<>"",NameYours&CHAR(10)&" and "&NameSpouse,NameYours)) -> Enter your name(s) on the sheet lableled '1040' | D31: Payer #6 | E31: Payer #7 | F31: Payer #8 | G31: Payer #9 | H31: Payer #10
C32: PAYER's name
C33: PAYER's Federal ID number
C34: Account number
B35: 1 | C35: Interest income | AA35: =ROUND(D35,0) -> 0 | AB35: =ROUND(E35,0) -> 0 | AC35: =ROUND(F35,0) -> 0 | AD35: =ROUND(G35,0) -> 0 | AE35: =ROUND(H35,0) -> 0
B36: 2 | C36: Early withdrawal penalty | AA36: =ROUND(D36,0) -> 0 | AB36: =ROUND(E36,0) -> 0 | AC36: =ROUND(F36,0) -> 0 | AD36: =ROUND(G36,0) -> 0 | AE36: =ROUND(H36,0) -> 0
B37: 3 | C37: Interest on U.S. Savings Bonds & Treas. Obligations | AA37: =ROUND(D37,0) -> 0 | AB37: =ROUND(E37,0) -> 0 | AC37: =ROUND(F37,0) -> 0 | AD37: =ROUND(G37,0) -> 0 | AE37: =ROUND(H37,0) -> 0
B38: 3A | C38: Include Line 3 on Schedule B, Line 1? (Y / N) | D38: N | E38: N | F38: N | G38: N | H38: N
B39: 4 | C39: Federal income tax withheld | AA39: =ROUND(D39,0) -> 0 | AB39: =ROUND(E39,0) -> 0 | AC39: =ROUND(F39,0) -> 0 | AD39: =ROUND(G39,0) -> 0 | AE39: =ROUND(H39,0) -> 0
B40: 5 | C40: Investment expenses | AA40: =ROUND(D40,0) -> 0 | AB40: =ROUND(E40,0) -> 0 | AC40: =ROUND(F40,0) -> 0 | AD40: =ROUND(G40,0) -> 0 | AE40: =ROUND(H40,0) -> 0
B41: 6 | C41: Foreign tax paid | I41: =IF(SUM(D41:H41)>0,"Check Form 1116, Foreign Tax Credit","") | AA41: =ROUND(D41,0) -> 0 | AB41: =ROUND(E41,0) -> 0 | AC41: =ROUND(F41,0) -> 0 | AD41: =ROUND(G41,0) -> 0 | AE41: =ROUND(H41,0) -> 0
...

Sheet 1099-DIV
B1: Information from Form 1099-DIV, Dividends and Distributions | K1: Notes
C2: =IF(Name_1st_Yours="","Enter your name(s) on the"&CHAR(10)&"sheet labeled '1040'",Names) -> Enter your name(s) on the sheet labeled '1040' | D2: Payer #1 | E2: Payer #2 | F2: Payer #3 | G2: Payer #4 | H2: Payer #5 | K2: Date:
C3: PAYER's name
C4: PAYER's Federal ID number
C5: Account number
B6: 1a | C6: Total ordinary dividends | I6: =IF(I25,"Error: All qualified dividends must be included in","") | AA6: =ROUND(D6,2) -> 0 | AB6: =ROUND(E6,2) -> 0 | AC6: =ROUND(F6,2) -> 0 | AD6: =ROUND(G6,2) -> 0 | AE6: =ROUND(H6,2) -> 0
B7: 1b | C7: Qualified dividends | I7: =IF(I25,"the Total ordinary dividend amount.","") | AA7: =ROUND(D7,2) -> 0 | AB7: =ROUND(E7,2) -> 0 | AC7: =ROUND(F7,2) -> 0 | AD7: =ROUND(G7,2) -> 0 | AE7: =ROUND(H7,2) -> 0
B8: 2a | C8: Total capital gain distr. | AA8: =ROUND(D8,2) -> 0 | AB8: =ROUND(E8,2) -> 0 | AC8: =ROUND(F8,2) -> 0 | AD8: =ROUND(G8,2) -> 0 | AE8: =ROUND(H8,2) -> 0
B9: 2b | C9: Unrecap. Sec. 1250 gain | AA9: =ROUND(D9,2) -> 0 | AB9: =ROUND(E9,2) -> 0 | AC9: =ROUND(F9,2) -> 0 | AD9: =ROUND(G9,2) -> 0 | AE9: =ROUND(H9,2) -> 0
B10: 2c | C10: Section 1202 gain | AA10: =ROUND(D10,2) -> 0 | AB10: =ROUND(E10,2) -> 0 | AC10: =ROUND(F10,2) -> 0 | AD10: =ROUND(G10,2) -> 0 | AE10: =ROUND(H10,2) -> 0
B11: 2d | C11: Collectibles (28%) gain | AA11: =ROUND(D11,2) -> 0 | AB11: =ROUND(E11,2) -> 0 | AC11: =ROUND(F11,2) -> 0 | AD11: =ROUND(G11,2) -> 0 | AE11: =ROUND(H11,2) -> 0
B12: 3 | C12: Nondividend distributions | AA12: =ROUND(D12,2) -> 0 | AB12: =ROUND(E12,2) -> 0 | AC12: =ROUND(F12,2) -> 0 | AD12: =ROUND(G12,2) -> 0 | AE12: =ROUND(H12,2) -> 0
B13: 4 | C13: Federal income tax withheld | AA13: =ROUND(D13,2) -> 0 | AB13: =ROUND(E13,2) -> 0 | AC13: =ROUND(F13,2) -> 0 | AD13: =ROUND(G13,2) -> 0 | AE13: =ROUND(H13,2) -> 0
B14: 5 | C14: Section 199A dividends | AA14: =ROUND(D14,2) -> 0 | AB14: =ROUND(E14,2) -> 0 | AC14: =ROUND(F14,2) -> 0 | AD14: =ROUND(G14,2) -> 0 | AE14: =ROUND(H14,2) -> 0
B15: 6 | C15: Investment expenses | AA15: =ROUND(D15,2) -> 0 | AB15: =ROUND(E15,2) -> 0 | AC15: =ROUND(F15,2) -> 0 | AD15: =ROUND(G15,2) -> 0 | AE15: =ROUND(H15,2) -> 0
B16: 7 | C16: Foreign tax paid | I16: =IF(SUM(D16:H16)>0,"Check Form 1116, Foreign Tax Credit","") | AA16: =ROUND(D16,2) -> 0 | AB16: =ROUND(E16,2) -> 0 | AC16: =ROUND(F16,2) -> 0 | AD16: =ROUND(G16,2) -> 0 | AE16: =ROUND(H16,2) -> 0
B17: 8 | C17: Foreign country or U.S. possession
B18: 9 | C18: Cash liquidation distributions | AA18: =ROUND(D18,2) -> 0 | AB18: =ROUND(E18,2) -> 0 | AC18: =ROUND(F18,2) -> 0 | AD18: =ROUND(G18,2) -> 0 | AE18: =ROUND(H18,2) -> 0
B19: 10 | C19: Noncash liquidation distributions | AA19: =ROUND(D19,2) -> 0 | AB19: =ROUND(E19,2) -> 0 | AC19: =ROUND(F19,2) -> 0 | AD19: =ROUND(G19,2) -> 0 | AE19: =ROUND(H19,2) -> 0
B20: 11 | C20: Exempt-interest dividends | AA20: =ROUND(D20,2) -> 0 | AB20: =ROUND(E20,2) -> 0 | AC20: =ROUND(F20,2) -> 0 | AD20: =ROUND(G20,2) -> 0 | AE20: =ROUND(H20,2) -> 0
B21: 12 | C21: Specified private activity bond interest dividends | AA21: =ROUND(D21,2) -> 0 | AB21: =ROUND(E21,2) -> 0 | AC21: =ROUND(F21,2) -> 0 | AD21: =ROUND(G21,2) -> 0 | AE21: =ROUND(H21,2) -> 0
B22: 13 | C22: State
B23: 14 | C23: State identification no.
B24: 15 | C24: State tax withheld | AA24: =ROUND(D24,2) -> 0 | AB24: =ROUND(E24,2) -> 0 | AC24: =ROUND(F24,2) -> 0 | AD24: =ROUND(G24,2) -> 0 | AE24: =ROUND(H24,2) -> 0
B25: Only bolded amounts are used in this spreadsheet. | D25: =D7>D6 -> FALSE | E25: =E7>E6 -> FALSE | F25: =F7>F6 -> FALSE | G25: =G7>G6 -> FALSE | H25: =H7>H6 -> FALSE | I25: =OR(D25:H25) -> FALSE
D26: =IF(D3<>"",D3,"") | E26: =IF(E3<>"",E3,"") | F26: =IF(F3<>"",F3,"") | G26: =IF(G3<>"",G3,"") | H26: =IF(H3<>"",H3,"")
D27: =IF(D4<>"", " - "&D4,"") | E27: =IF(E4<>"", " - "&E4,"") | F27: =IF(F4<>"", " - "&F4,"") | G27: =IF(G4<>"", " - "&G4,"") | H27: =IF(H4<>"", " - "&H4,"")
D28: =IF(D5<>""," - "&D5,"") | E28: =IF(E5<>""," - "&E5,"") | F28: =IF(F5<>""," - "&F5,"") | G28: =IF(G5<>""," - "&G5,"") | H28: =IF(H5<>""," - "&H5,"")
D29: =IF(D6="","",D26&D27&D28) | E29: =IF(E6="","",E26&E27&E28) | F29: =IF(F6="","",F26&F27&F28) | G29: =IF(G6="","",G26&G27&G28) | H29: =IF(H6="","",H26&H27&H28)
C30: =IF(Name_1st_Yours="","Enter your name(s) on the"&CHAR(10)&"sheet labeled '1040'",Names) -> Enter your name(s) on the sheet labeled '1040' | D30: Payer #6 | E30: Payer #7 | F30: Payer #8 | G30: Payer #9 | H30: Payer #10
C31: PAYER's name
C32: PAYER's Federal ID number
C33: Account number
B34: 1a | C34: Total ordinary dividends | I34: =IF(I53,"Error: All qualified dividends must be included in","") | AA34: =ROUND(D34,2) -> 0 | AB34: =ROUND(E34,2) -> 0 | AC34: =ROUND(F34,2) -> 0 | AD34: =ROUND(G34,2) -> 0 | AE34: =ROUND(H34,2) -> 0
B35: 1b | C35: Qualified dividends | I35: =IF(I53,"the Total ordinary dividend amount.","") | AA35: =ROUND(D35,2) -> 0 | AB35: =ROUND(E35,2) -> 0 | AC35: =ROUND(F35,2) -> 0 | AD35: =ROUND(G35,2) -> 0 | AE35: =ROUND(H35,2) -> 0
B36: 2a | C36: Total capital gain distr. | AA36: =ROUND(D36,2) -> 0 | AB36: =ROUND(E36,2) -> 0 | AC36: =ROUND(F36,2) -> 0 | AD36: =ROUND(G36,2) -> 0 | AE36: =ROUND(H36,2) -> 0
B37: 2b | C37: Unrecap. Sec. 1250 gain | AA37: =ROUND(D37,2) -> 0 | AB37: =ROUND(E37,2) -> 0 | AC37: =ROUND(F37,2) -> 0 | AD37: =ROUND(G37,2) -> 0 | AE37: =ROUND(H37,2) -> 0
B38: 2c | C38: Section 1202 gain | AA38: =ROUND(D38,2) -> 0 | AB38: =ROUND(E38,2) -> 0 | AC38: =ROUND(F38,2) -> 0 | AD38: =ROUND(G38,2) -> 0 | AE38: =ROUND(H38,2) -> 0
B39: 2d | C39: Collectibles (28%) gain | AA39: =ROUND(D39,2) -> 0 | AB39: =ROUND(E39,2) -> 0 | AC39: =ROUND(F39,2) -> 0 | AD39: =ROUND(G39,2) -> 0 | AE39: =ROUND(H39,2) -> 0
B40: 3 | C40: Nondividend distributions | AA40: =ROUND(D40,2) -> 0 | AB40: =ROUND(E40,2) -> 0 | AC40: =ROUND(F40,2) -> 0 | AD40: =ROUND(G40,2) -> 0 | AE40: =ROUND(H40,2) -> 0
...

Sheet 1099-G
B1: Form 1099-G, Certain Government Payments | E1: =IF(FALSE,"After Form 1040 and Schedule 1 are complete,"&CHAR(10)&" be sure to review 'Sch. 1 Line 8 WS', line 1.",IF(FALSE,"'Sch. 1 Line 8 WS', line 1, has been Updated.","")) | L1: Notes
C2: =IF(Name_1st_Yours="","Enter your name on the"&CHAR(10)&"sheet labeled '1040'",NameYours) -> Enter your name on the sheet labeled '1040' | D2: Payer #1 | E2: Payer #2 | F2: Payer #3 | G2: Payer #4 | H2: Payer #5 | I2: Your Total | J2: Used at:
C3: PAYER's name
C4: PAYER's TIN
C5: Account number
B6: 1 | C6: Unemployment Compensation | I6: =ROUND(SUM(D6:H6),0) -> 0 | J6: Sch. 1 Line 8 WS', line 7
B7: 2 | C7: State or local income tax refunds, credits, offsets | I7: =ROUND(SUM(D7:H7),0) -> 0 | J7: =IF(Needs_SALT," See sheet labeled"," 'Sch. 1, Line 1 (SALT)', line 1 [State & local tax]") -> 'Sch. 1, Line 1 (SALT)', line 1 [State & local tax]
B8: 3 | C8: Box 2 amount is for tax year | I8: --- | J8: =IF(Needs_SALT,"'Sch. 1, Line 1 (SALT)'. (State & Local Tax)","")
B9: 4 | C9: Federal income tax withheld | I9: =ROUND(SUM(D9:H9),0) -> 0
B10: 5 | C10: RTAA Payments | I10: =ROUND(SUM(D10:H10),0) -> 0
B11: 6 | C11: Taxable grants | I11: =ROUND(SUM(D11:H11),0) -> 0
B12: 7a | C12: Agriculture payments - Disaster payments | I12: =ROUND(SUM(D12:H12),0) -> 0
B13: 7b | C13: Agriculture payments - Other payments | I13: =ROUND(SUM(D13:H13),0) -> 0 | J13: =AND(D13="",E13="",F13="",G13="",I13="") -> FALSE
B14: 8 | C14: Check if box 2 is trade or business income
B15: 9 | C15: Market gain | I15: =ROUND(SUM(D15:H15),0) -> 0 | J15: =AND(D15="",E15="",F15="",G15="",I15="") -> FALSE
B16: 10a | C16: State
B17: 10b | C17: State identification no.
B18: 11 | C18: State income tax withheld | I18: =ROUND(SUM(D18:H18),0) -> 0
B19: Only bolded amounts are used in this spreadsheet.
I20: =IF(I3<>"",I3,"")
C21: =IF(Name_1st_Sp="","Enter your spouse's name on"&CHAR(10)&"the sheet labeled '1040'",NameSpouse) -> Enter your spouse's name on the sheet labeled '1040' | D21: Payer #1 | E21: Payer #2 | F21: Payer #3 | G21: Payer #4 | H21: Spouse Total | I21: Total | J21: Used at:
C22: PAYER's name
C23: PAYER's Federal ID number
C24: Account number | J24: =SUM(ForeignTaxPaid_INT,ForeignTaxPaid_DIV) -> 0
B25: 1 | C25: Unemployment Compensation | H25: =ROUND(SUM(D25:G25),0) -> 0 | I25: =SUM(UCE_You,UCE_Spouse) -> 0 | J25: Sch. 1 Line 8 WS', line 8 / Sch. 1, line 7
B26: 2 | C26: State or local income tax refunds, credits, offsets | H26: =ROUND(SUM(D26:G26),0) -> 0 | I26: =SUM(I7,H26) -> 0 | J26: =IF(Needs_SALT," See sheet labeled"," 'Sch. 1, Line 1 (SALT)', line 1 [State & local tax]") -> 'Sch. 1, Line 1 (SALT)', line 1 [State & local tax]
B27: 3 | C27: Box 2 amount is for tax year | H27: --- | I27: --- | J27: =IF(Needs_SALT," 'Sch. 1, Line 1 (SALT)'. (State & Local Tax)","")
B28: 4 | C28: Federal income tax withheld | H28: =ROUND(SUM(D28:G28),0) -> 0 | I28: =SUM(I9,H28) -> 0 | J28: 1040, line 25b
B29: 5 | C29: RTAA Payments | H29: =ROUND(SUM(D29:G29),0) -> 0 | I29: =SUM(I10,H29) -> 0 | J29: Sch. 1, line 8
B30: 6 | C30: Taxable grants | H30: =ROUND(SUM(D30:G30),0) -> 0 | I30: =SUM(I11,H30) -> 0 | J30: Sch. 1, line 8 and 'Earned Inc WS', line 4a
B31: 7a | C31: Agriculture payments - Disaster payments | H31: =ROUND(SUM(D31:G31),0) -> 0 | I31: =SUM(I12,H31) -> 0 | J31: Sch. F, Line 6a
B32: 7b | C32: Agriculture payments - Other payments | H32: =ROUND(SUM(D32:G32),0) -> 0 | I32: =SUM(I13,H32) -> 0 | J32: Sch. F, Line 4a
B33: 8 | C33: Check if box 2 is trade or business income | J33: =AND(J13,D31="",E31="",F31="",G31="") -> FALSE
B34: 9 | C34: Market gain | H34: =ROUND(SUM(D34:G34),0) -> 0 | I34: =SUM(I15,H34) -> 0 | J34: Sch. F, Line 4a
B35: 10a | C35: State | J35: =AND(J15,D33="",E33="",F33="",G33="") -> FALSE
B36: 10b | C36: State identification no.
B37: 11 | C37: State income tax withheld | H37: =ROUND(SUM(D37:G37),0) -> 0 | I37: =SUM(I18,H37) -> 0 | J37: Sch. A, Line 5a
B38: Only bolded amounts are used in this spreadsheet.
C43: Table of Contents

Sheet 1099-MISC
C3: This form has yet to be implemented.
C5: Download and follow IRS instructions for where the information and amounts should be entered.
C7: NOTE: | D7: Amounts of more than $600 will NOT typically be reported on Schedule 1 (Form 1040), Line 8.
C9: ="Instructions for Form 1099-MISC may be downloaded from the IRS:" -> Instructions for Form 1099-MISC may be downloaded from the IRS:
C10: https://www.irs.gov/pub/irs-pdf/f1099msc.pdf
C12: ="Form 1099-MISC may be downloaded from the IRS:" -> Form 1099-MISC may be downloaded from the IRS:
C13: https://www.irs.gov/pub/irs-pdf/f1099msc_21.pdf
C72: Table of Contents

Sheet 1099-R
B1: Information from Form 1099-R, Distributions From Pensions, Annuities, Retirement or Profit-Sharing Plans, IRAs, Insurance Contracts, etc. | AT1: Notes
C2: =IF(Name_1st_Yours="","Enter your name on the"&CHAR(10)&"sheet labeled '1040'",NameYours) -> Enter your name on the sheet labeled '1040' | D2: Enter payer's name here. | E2: Payer #2 | F2: Payer #3 | G2: Payer #4 | H2: Payer #5 | I2: Payer #6 | J2: Payer #7 | K2: Payer #8 | L2: Payer #9 | M2: Total IRAs | N2: Total Pension / Annuities | O2: Qualified CONVersion to ROTH IRA | U2: IRA | AE2: P/A | AO2: CONV
C3: Enter "IRA" or "P/A" or "CONV" >>> | M3: IRA | N3: P/A | O3: CONV | Q3: =NOT(AND(ISERROR(FIND("IRA",D3,1)),ISERROR(FIND("ira",D3,1)))) -> FALSE | R3: =NOT(AND(ISERROR(FIND("IRA",E3,1)),ISERROR(FIND("ira",E3,1)))) -> FALSE | S3: =NOT(AND(ISERROR(FIND("IRA",F3,1)),ISERROR(FIND("ira",F3,1)))) -> FALSE | T3: =NOT(AND(ISERROR(FIND("IRA",G3,1)),ISERROR(FIND("ira",G3,1)))) -> FALSE | U3: =NOT(AND(ISERROR(FIND("IRA",H3,1)),ISERROR(FIND("ira",H3,1)))) -> FALSE | V3: =NOT(AND(ISERROR(FIND("IRA",I3,1)),ISERROR(FIND("ira",I3,1)))) -> FALSE | W3: =NOT(AND(ISERROR(FIND("IRA",J3,1)),ISERROR(FIND("ira",J3,1)))) -> FALSE | X3: =NOT(AND(ISERROR(FIND("IRA",K3,1)),ISERROR(FIND("ira",K3,1)))) -> FALSE | Y3: =NOT(AND(ISERROR(FIND("IRA",L3,1)),ISERROR(FIND("ira",L3,1)))) -> FALSE | AA3: =NOT(AND(ISERROR(FIND("P/A",D3,1)),ISERROR(FIND("p/a",D3,1)))) -> FALSE | AB3: =NOT(AND(ISERROR(FIND("P/A",E3,1)),ISERROR(FIND("p/a",E3,1)))) -> FALSE | AC3: =NOT(AND(ISERROR(FIND("P/A",F3,1)),ISERROR(FIND("p/a",F3,1)))) -> FALSE | AD3: =NOT(AND(ISERROR(FIND("P/A",G3,1)),ISERROR(FIND("p/a",G3,1)))) -> FALSE | AE3: =NOT(AND(ISERROR(FIND("P/A",H3,1)),ISERROR(FIND("p/a",H3,1)))) -> FALSE | AF3: =NOT(AND(ISERROR(FIND("P/A",I3,1)),ISERROR(FIND("p/a",I3,1)))) -> FALSE | AG3: =NOT(AND(ISERROR(FIND("P/A",J3,1)),ISERROR(FIND("p/a",J3,1)))) -> FALSE | AH3: =NOT(AND(ISERROR(FIND("P/A",K3,1)),ISERROR(FIND("p/a",K3,1)))) -> FALSE | AI3: =NOT(AND(ISERROR(FIND("P/A",L3,1)),ISERROR(FIND("p/a",L3,1)))) -> FALSE | AK3: =NOT(AND(ISERROR(FIND("CONV",D3,1)),ISERROR(FIND("conv",D3,1)))) -> FALSE | AL3: =NOT(AND(ISERROR(FIND("CONV",E3,1)),ISERROR(FIND("conv",E3,1)))) -> FALSE | AM3: =NOT(AND(ISERROR(FIND("CONV",F3,1)),ISERROR(FIND("conv",F3,1)))) -> FALSE | AN3: =NOT(AND(ISERROR(FIND("CONV",G3,1)),ISERROR(FIND("conv",G3,1)))) -> FALSE | AO3: =NOT(AND(ISERROR(FIND("CONV",H3,1)),ISERROR(FIND("conv",H3,1)))) -> FALSE | AP3: =NOT(AND(ISERROR(FIND("CONV",I3,1)),ISERROR(FIND("conv",I3,1)))) -> FALSE | AQ3: =NOT(AND(ISERROR(FIND("CONV",J3,1)),ISERROR(FIND("conv",J3,1)))) -> FALSE | AR3: =NOT(AND(ISERROR(FIND("CONV",K3,1)),ISERROR(FIND("conv",K3,1)))) -> FALSE | AS3: =NOT(AND(ISERROR(FIND("CONV",L3,1)),ISERROR(FIND("conv",L3,1)))) -> FALSE
B4: 1 | C4: Gross distribution | M4: =SUM(Q4:Y4) -> 0 | N4: =SUM(AA4:AI4) -> 0 | O4: =SUM(AK4:AS4) -> 0 | Q4: =IF(Q$3,ROUND(D4,0),0) -> 0 | R4: =IF(R$3,ROUND(E4,0),0) -> 0 | S4: =IF(S$3,ROUND(F4,0),0) -> 0 | T4: =IF(T$3,ROUND(G4,0),0) -> 0 | U4: =IF(U$3,ROUND(H4,0),0) -> 0 | V4: =IF(V$3,ROUND(I4,0),0) -> 0 | W4: =IF(W$3,ROUND(J4,0),0) -> 0 | X4: =IF(X$3,ROUND(K4,0),0) -> 0 | Y4: =IF(Y$3,ROUND(L4,0),0) -> 0 | AA4: =IF(AA$3,ROUND(D4,0),0) -> 0 | AB4: =IF(AB$3,ROUND(E4,0),0) -> 0 | AC4: =IF(AC$3,ROUND(F4,0),0) -> 0 | AD4: =IF(AD$3,ROUND(G4,0),0) -> 0 | AE4: =IF(AE$3,ROUND(H4,0),0) -> 0 | AF4: =IF(AF$3,ROUND(I4,0),0) -> 0 | AG4: =IF(AG$3,ROUND(J4,0),0) -> 0 | AH4: =IF(AH$3,ROUND(K4,0),0) -> 0 | AI4: =IF(AI$3,ROUND(L4,0),0) -> 0 | AK4: =IF(AK$3,ROUND(D4,0),0) -> 0 | AL4: =IF(AL$3,ROUND(E4,0),0) -> 0 | AM4: =IF(AM$3,ROUND(F4,0),0) -> 0 | AN4: =IF(AN$3,ROUND(G4,0),0) -> 0 | AO4: =IF(AO$3,ROUND(H4,0),0) -> 0 | AP4: =IF(AP$3,ROUND(I4,0),0) -> 0 | AQ4: =IF(AQ$3,ROUND(J4,0),0) -> 0 | AR4: =IF(AR$3,ROUND(K4,0),0) -> 0 | AS4: =IF(AS$3,ROUND(L4,0),0) -> 0
B5: 2a | C5: Taxable amount | M5: =SUM(Q5:Y5) -> 0 | N5: =SUM(AA5:AI5) -> 0 | O5: =SUM(AK5:AS5) -> 0 | Q5: =IF(Q$3,ROUND(D5,0),0) -> 0 | R5: =IF(R$3,ROUND(E5,0),0) -> 0 | S5: =IF(S$3,ROUND(F5,0),0) -> 0 | T5: =IF(T$3,ROUND(G5,0),0) -> 0 | U5: =IF(U$3,ROUND(H5,0),0) -> 0 | V5: =IF(V$3,ROUND(I5,0),0) -> 0 | W5: =IF(W$3,ROUND(J5,0),0) -> 0 | X5: =IF(X$3,ROUND(K5,0),0) -> 0 | Y5: =IF(Y$3,ROUND(L5,0),0) -> 0 | AA5: =IF(AA$3,ROUND(D5,0),0) -> 0 | AB5: =IF(AB$3,ROUND(E5,0),0) -> 0 | AC5: =IF(AC$3,ROUND(F5,0),0) -> 0 | AD5: =IF(AD$3,ROUND(G5,0),0) -> 0 | AE5: =IF(AE$3,ROUND(H5,0),0) -> 0 | AF5: =IF(AF$3,ROUND(I5,0),0) -> 0 | AG5: =IF(AG$3,ROUND(J5,0),0) -> 0 | AH5: =IF(AH$3,ROUND(K5,0),0) -> 0 | AI5: =IF(AI$3,ROUND(L5,0),0) -> 0 | AK5: =IF(AK$3,ROUND(D5,0),0) -> 0 | AL5: =IF(AL$3,ROUND(E5,0),0) -> 0 | AM5: =IF(AM$3,ROUND(F5,0),0) -> 0 | AN5: =IF(AN$3,ROUND(G5,0),0) -> 0 | AO5: =IF(AO$3,ROUND(H5,0),0) -> 0 | AP5: =IF(AP$3,ROUND(I5,0),0) -> 0 | AQ5: =IF(AQ$3,ROUND(J5,0),0) -> 0 | AR5: =IF(AR$3,ROUND(K5,0),0) -> 0 | AS5: =IF(AS$3,ROUND(L5,0),0) -> 0
B6: 2b | C6: Taxable amount not determined / total distr. | M6: =" - - - -" -> - - - - | N6: =" - - - -" -> - - - - | O6: =" - - - -" -> - - - -
B7: 3 | C7: Capital gain (included in box 2a) | M7: =SUM(Q7:Y7) -> 0 | N7: =SUM(AA7:AI7) -> 0 | O7: =SUM(AK7:AS7) -> 0 | Q7: =IF(Q$3,ROUND(D7,0),0) -> 0 | R7: =IF(R$3,ROUND(E7,0),0) -> 0 | S7: =IF(S$3,ROUND(F7,0),0) -> 0 | T7: =IF(T$3,ROUND(G7,0),0) -> 0 | U7: =IF(U$3,ROUND(H7,0),0) -> 0 | V7: =IF(V$3,ROUND(I7,0),0) -> 0 | W7: =IF(W$3,ROUND(J7,0),0) -> 0 | X7: =IF(X$3,ROUND(K7,0),0) -> 0 | Y7: =IF(Y$3,ROUND(L7,0),0) -> 0 | AA7: =IF(AA$3,ROUND(D7,0),0) -> 0 | AB7: =IF(AB$3,ROUND(E7,0),0) -> 0 | AC7: =IF(AC$3,ROUND(F7,0),0) -> 0 | AD7: =IF(AD$3,ROUND(G7,0),0) -> 0 | AE7: =IF(AE$3,ROUND(H7,0),0) -> 0 | AF7: =IF(AF$3,ROUND(I7,0),0) -> 0 | AG7: =IF(AG$3,ROUND(J7,0),0) -> 0 | AH7: =IF(AH$3,ROUND(K7,0),0) -> 0 | AI7: =IF(AI$3,ROUND(L7,0),0) -> 0 | AK7: =IF(AK$3,ROUND(D7,0),0) -> 0 | AL7: =IF(AL$3,ROUND(E7,0),0) -> 0 | AM7: =IF(AM$3,ROUND(F7,0),0) -> 0 | AN7: =IF(AN$3,ROUND(G7,0),0) -> 0 | AO7: =IF(AO$3,ROUND(H7,0),0) -> 0 | AP7: =IF(AP$3,ROUND(I7,0),0) -> 0 | AQ7: =IF(AQ$3,ROUND(J7,0),0) -> 0 | AR7: =IF(AR$3,ROUND(K7,0),0) -> 0 | AS7: =IF(AS$3,ROUND(L7,0),0) -> 0
B8: 4 | C8: Federal income tax withheld | M8: =SUM(Q8:Y8) -> 0 | N8: =SUM(AA8:AI8) -> 0 | O8: =SUM(AK8:AS8) -> 0 | Q8: =IF(Q$3,ROUND(D8,0),0) -> 0 | R8: =IF(R$3,ROUND(E8,0),0) -> 0 | S8: =IF(S$3,ROUND(F8,0),0) -> 0 | T8: =IF(T$3,ROUND(G8,0),0) -> 0 | U8: =IF(U$3,ROUND(H8,0),0) -> 0 | V8: =IF(V$3,ROUND(I8,0),0) -> 0 | W8: =IF(W$3,ROUND(J8,0),0) -> 0 | X8: =IF(X$3,ROUND(K8,0),0) -> 0 | Y8: =IF(Y$3,ROUND(L8,0),0) -> 0 | AA8: =IF(AA$3,ROUND(D8,0),0) -> 0 | AB8: =IF(AB$3,ROUND(E8,0),0) -> 0 | AC8: =IF(AC$3,ROUND(F8,0),0) -> 0 | AD8: =IF(AD$3,ROUND(G8,0),0) -> 0 | AE8: =IF(AE$3,ROUND(H8,0),0) -> 0 | AF8: =IF(AF$3,ROUND(I8,0),0) -> 0 | AG8: =IF(AG$3,ROUND(J8,0),0) -> 0 | AH8: =IF(AH$3,ROUND(K8,0),0) -> 0 | AI8: =IF(AI$3,ROUND(L8,0),0) -> 0 | AK8: =IF(AK$3,ROUND(D8,0),0) -> 0 | AL8: =IF(AL$3,ROUND(E8,0),0) -> 0 | AM8: =IF(AM$3,ROUND(F8,0),0) -> 0 | AN8: =IF(AN$3,ROUND(G8,0),0) -> 0 | AO8: =IF(AO$3,ROUND(H8,0),0) -> 0 | AP8: =IF(AP$3,ROUND(I8,0),0) -> 0 | AQ8: =IF(AQ$3,ROUND(J8,0),0) -> 0 | AR8: =IF(AR$3,ROUND(K8,0),0) -> 0 | AS8: =IF(AS$3,ROUND(L8,0),0) -> 0
B9: 5 | C9: Employee contributions / Insurance premiums / Designated Roth IRA contributions | M9: =SUM(Q9:Y9) -> 0 | N9: =SUM(AA9:AI9) -> 0 | O9: =SUM(AK9:AS9) -> 0 | Q9: =IF(Q$3,ROUND(D9,0),0) -> 0 | R9: =IF(R$3,ROUND(E9,0),0) -> 0 | S9: =IF(S$3,ROUND(F9,0),0) -> 0 | T9: =IF(T$3,ROUND(G9,0),0) -> 0 | U9: =IF(U$3,ROUND(H9,0),0) -> 0 | V9: =IF(V$3,ROUND(I9,0),0) -> 0 | W9: =IF(W$3,ROUND(J9,0),0) -> 0 | X9: =IF(X$3,ROUND(K9,0),0) -> 0 | Y9: =IF(Y$3,ROUND(L9,0),0) -> 0 | AA9: =IF(AA$3,ROUND(D9,0),0) -> 0 | AB9: =IF(AB$3,ROUND(E9,0),0) -> 0 | AC9: =IF(AC$3,ROUND(F9,0),0) -> 0 | AD9: =IF(AD$3,ROUND(G9,0),0) -> 0 | AE9: =IF(AE$3,ROUND(H9,0),0) -> 0 | AF9: =IF(AF$3,ROUND(I9,0),0) -> 0 | AG9: =IF(AG$3,ROUND(J9,0),0) -> 0 | AH9: =IF(AH$3,ROUND(K9,0),0) -> 0 | AI9: =IF(AI$3,ROUND(L9,0),0) -> 0 | AK9: =IF(AK$3,ROUND(D9,0),0) -> 0 | AL9: =IF(AL$3,ROUND(E9,0),0) -> 0 | AM9: =IF(AM$3,ROUND(F9,0),0) -> 0 | AN9: =IF(AN$3,ROUND(G9,0),0) -> 0 | AO9: =IF(AO$3,ROUND(H9,0),0) -> 0 | AP9: =IF(AP$3,ROUND(I9,0),0) -> 0 | AQ9: =IF(AQ$3,ROUND(J9,0),0) -> 0 | AR9: =IF(AR$3,ROUND(K9,0),0) -> 0 | AS9: =IF(AS$3,ROUND(L9,0),0) -> 0
B10: 6 | C10: Net unrealized appreciation in employer's securities | M10: =SUM(Q10:Y10) -> 0 | N10: =SUM(AA10:AI10) -> 0 | O10: =SUM(AK10:AS10) -> 0 | Q10: =IF(Q$3,ROUND(D10,0),0) -> 0 | R10: =IF(R$3,ROUND(E10,0),0) -> 0 | S10: =IF(S$3,ROUND(F10,0),0) -> 0 | T10: =IF(T$3,ROUND(G10,0),0) -> 0 | U10: =IF(U$3,ROUND(H10,0),0) -> 0 | V10: =IF(V$3,ROUND(I10,0),0) -> 0 | W10: =IF(W$3,ROUND(J10,0),0) -> 0 | X10: =IF(X$3,ROUND(K10,0),0) -> 0 | Y10: =IF(Y$3,ROUND(L10,0),0) -> 0 | AA10: =IF(AA$3,ROUND(D10,0),0) -> 0 | AB10: =IF(AB$3,ROUND(E10,0),0) -> 0 | AC10: =IF(AC$3,ROUND(F10,0),0) -> 0 | AD10: =IF(AD$3,ROUND(G10,0),0) -> 0 | AE10: =IF(AE$3,ROUND(H10,0),0) -> 0 | AF10: =IF(AF$3,ROUND(I10,0),0) -> 0 | AG10: =IF(AG$3,ROUND(J10,0),0) -> 0 | AH10: =IF(AH$3,ROUND(K10,0),0) -> 0 | AI10: =IF(AI$3,ROUND(L10,0),0) -> 0 | AK10: =IF(AK$3,ROUND(D10,0),0) -> 0 | AL10: =IF(AL$3,ROUND(E10,0),0) -> 0 | AM10: =IF(AM$3,ROUND(F10,0),0) -> 0 | AN10: =IF(AN$3,ROUND(G10,0),0) -> 0 | AO10: =IF(AO$3,ROUND(H10,0),0) -> 0 | AP10: =IF(AP$3,ROUND(I10,0),0) -> 0 | AQ10: =IF(AQ$3,ROUND(J10,0),0) -> 0 | AR10: =IF(AR$3,ROUND(K10,0),0) -> 0 | AS10: =IF(AS$3,ROUND(L10,0),0) -> 0
B11: 7 | C11: Distribution code(s) (Code D only) | M11: =" - - - -" -> - - - - | N11: =" - - - -" -> - - - - | O11: =" - - - -" -> - - - - | AK11: =IF(AK$3,ROUND(D11,0),0) -> 0 | AL11: =IF(AL$3,ROUND(E11,0),0) -> 0 | AM11: =IF(AM$3,ROUND(F11,0),0) -> 0 | AN11: =IF(AN$3,ROUND(G11,0),0) -> 0 | AO11: =IF(AO$3,ROUND(H11,0),0) -> 0 | AP11: =IF(AP$3,ROUND(I11,0),0) -> 0 | AQ11: =IF(AQ$3,ROUND(J11,0),0) -> 0 | AR11: =IF(AR$3,ROUND(K11,0),0) -> 0 | AS11: =IF(AS$3,ROUND(L11,0),0) -> 0
B12: 8 | C12: Other | M12: =SUM(Q12:Y12) -> 0 | N12: =SUM(AA12:AI12) -> 0 | O12: =SUM(AK12:AS12) -> 0 | Q12: =IF(Q$3,ROUND(D12,0),0) -> 0 | R12: =IF(R$3,ROUND(E12,0),0) -> 0 | S12: =IF(S$3,ROUND(F12,0),0) -> 0 | T12: =IF(T$3,ROUND(G12,0),0) -> 0 | U12: =IF(U$3,ROUND(H12,0),0) -> 0 | V12: =IF(V$3,ROUND(I12,0),0) -> 0 | W12: =IF(W$3,ROUND(J12,0),0) -> 0 | X12: =IF(X$3,ROUND(K12,0),0) -> 0 | Y12: =IF(Y$3,ROUND(L12,0),0) -> 0 | AA12: =IF(AA$3,ROUND(D12,0),0) -> 0 | AB12: =IF(AB$3,ROUND(E12,0),0) -> 0 | AC12: =IF(AC$3,ROUND(F12,0),0) -> 0 | AD12: =IF(AD$3,ROUND(G12,0),0) -> 0 | AE12: =IF(AE$3,ROUND(H12,0),0) -> 0 | AF12: =IF(AF$3,ROUND(I12,0),0) -> 0 | AG12: =IF(AG$3,ROUND(J12,0),0) -> 0 | AH12: =IF(AH$3,ROUND(K12,0),0) -> 0 | AI12: =IF(AI$3,ROUND(L12,0),0) -> 0 | AK12: =IF(AK$3,ROUND(D12,0),0) -> 0 | AL12: =IF(AL$3,ROUND(E12,0),0) -> 0 | AM12: =IF(AM$3,ROUND(F12,0),0) -> 0 | AN12: =IF(AN$3,ROUND(G12,0),0) -> 0 | AO12: =IF(AO$3,ROUND(H12,0),0) -> 0 | AP12: =IF(AP$3,ROUND(I12,0),0) -> 0 | AQ12: =IF(AQ$3,ROUND(J12,0),0) -> 0 | AR12: =IF(AR$3,ROUND(K12,0),0) -> 0 | AS12: =IF(AS$3,ROUND(L12,0),0) -> 0
B13: 9a | C13: Your percentage of total distribution | M13: =SUM(Q13:Y13) -> 0 | N13: =SUM(AA13:AI13) -> 0 | O13: =SUM(AK13:AS13) -> 0 | Q13: =IF(Q3,D13,0) -> 0 | R13: =IF(R3,E13,0) -> 0 | S13: =IF(S3,F13,0) -> 0 | T13: =IF(T3,G13,0) -> 0 | U13: =IF(U3,H13,0) -> 0 | V13: =IF(V3,I13,0) -> 0 | W13: =IF(W3,J13,0) -> 0 | X13: =IF(X3,K13,0) -> 0 | Y13: =IF(Y3,L13,0) -> 0 | AA13: =IF(AA3,D13,0) -> 0 | AB13: =IF(AB3,E13,0) -> 0 | AC13: =IF(AC3,F13,0) -> 0 | AD13: =IF(AD3,G13,0) -> 0 | AE13: =IF(AE3,H13,0) -> 0 | AF13: =IF(AF3,I13,0) -> 0 | AG13: =IF(AG3,J13,0) -> 0 | AH13: =IF(AH3,K13,0) -> 0 | AI13: =IF(AI3,L13,0) -> 0 | AK13: =IF(AK3,D13,0) -> 0 | AL13: =IF(AL3,E13,0) -> 0 | AM13: =IF(AM3,F13,0) -> 0 | AN13: =IF(AN3,G13,0) -> 0 | AO13: =IF(AO3,H13,0) -> 0 | AP13: =IF(AP3,I13,0) -> 0 | AQ13: =IF(AQ3,J13,0) -> 0 | AR13: =IF(AR3,K13,0) -> 0 | AS13: =IF(AS3,L13,0) -> 0
B14: 9b | C14: Total employee contributions | M14: =SUM(Q14:Y14) -> 0 | N14: =SUM(AA14:AI14) -> 0 | O14: =SUM(AK14:AS14) -> 0 | Q14: =IF(Q$3,ROUND(D14,0),0) -> 0 | R14: =IF(R$3,ROUND(E14,0),0) -> 0 | S14: =IF(S$3,ROUND(F14,0),0) -> 0 | T14: =IF(T$3,ROUND(G14,0),0) -> 0 | U14: =IF(U$3,ROUND(H14,0),0) -> 0 | V14: =IF(V$3,ROUND(I14,0),0) -> 0 | W14: =IF(W$3,ROUND(J14,0),0) -> 0 | X14: =IF(X$3,ROUND(K14,0),0) -> 0 | Y14: =IF(Y$3,ROUND(L14,0),0) -> 0 | AA14: =IF(AA$3,ROUND(D14,0),0) -> 0 | AB14: =IF(AB$3,ROUND(E14,0),0) -> 0 | AC14: =IF(AC$3,ROUND(F14,0),0) -> 0 | AD14: =IF(AD$3,ROUND(G14,0),0) -> 0 | AE14: =IF(AE$3,ROUND(H14,0),0) -> 0 | AF14: =IF(AF$3,ROUND(I14,0),0) -> 0 | AG14: =IF(AG$3,ROUND(J14,0),0) -> 0 | AH14: =IF(AH$3,ROUND(K14,0),0) -> 0 | AI14: =IF(AI$3,ROUND(L14,0),0) -> 0 | AK14: =IF(AK$3,ROUND(D14,0),0) -> 0 | AL14: =IF(AL$3,ROUND(E14,0),0) -> 0 | AM14: =IF(AM$3,ROUND(F14,0),0) -> 0 | AN14: =IF(AN$3,ROUND(G14,0),0) -> 0 | AO14: =IF(AO$3,ROUND(H14,0),0) -> 0 | AP14: =IF(AP$3,ROUND(I14,0),0) -> 0 | AQ14: =IF(AQ$3,ROUND(J14,0),0) -> 0 | AR14: =IF(AR$3,ROUND(K14,0),0) -> 0 | AS14: =IF(AS$3,ROUND(L14,0),0) -> 0
B15: 10 | C15: Amount allocable to IRR within 5 years | M15: =SUM(Q15:Y15) -> 0 | N15: =SUM(AA15:AI15) -> 0 | O15: =SUM(AK15:AS15) -> 0 | Q15: =IF(Q$3,ROUND(D15,0),0) -> 0 | R15: =IF(R$3,ROUND(E15,0),0) -> 0 | S15: =IF(S$3,ROUND(F15,0),0) -> 0 | T15: =IF(T$3,ROUND(G15,0),0) -> 0 | U15: =IF(U$3,ROUND(H15,0),0) -> 0 | V15: =IF(V$3,ROUND(I15,0),0) -> 0 | W15: =IF(W$3,ROUND(J15,0),0) -> 0 | X15: =IF(X$3,ROUND(K15,0),0) -> 0 | Y15: =IF(Y$3,ROUND(L15,0),0) -> 0 | AA15: =IF(AA$3,ROUND(D15,0),0) -> 0 | AB15: =IF(AB$3,ROUND(E15,0),0) -> 0 | AC15: =IF(AC$3,ROUND(F15,0),0) -> 0 | AD15: =IF(AD$3,ROUND(G15,0),0) -> 0 | AE15: =IF(AE$3,ROUND(H15,0),0) -> 0 | AF15: =IF(AF$3,ROUND(I15,0),0) -> 0 | AG15: =IF(AG$3,ROUND(J15,0),0) -> 0 | AH15: =IF(AH$3,ROUND(K15,0),0) -> 0 | AI15: =IF(AI$3,ROUND(L15,0),0) -> 0 | AK15: =IF(AK$3,ROUND(D15,0),0) -> 0 | AL15: =IF(AL$3,ROUND(E15,0),0) -> 0 | AM15: =IF(AM$3,ROUND(F15,0),0) -> 0 | AN15: =IF(AN$3,ROUND(G15,0),0) -> 0 | AO15: =IF(AO$3,ROUND(H15,0),0) -> 0 | AP15: =IF(AP$3,ROUND(I15,0),0) -> 0 | AQ15: =IF(AQ$3,ROUND(J15,0),0) -> 0 | AR15: =IF(AR$3,ROUND(K15,0),0) -> 0 | AS15: =IF(AS$3,ROUND(L15,0),0) -> 0
B16: 11 | C16: 1st year of desig. Roth contrib. | M16: =SUM(Q16:Y16) -> 0 | N16: =SUM(AA16:AI16) -> 0 | O16: =SUM(AK16:AS16) -> 0 | Q16: =IF(Q$3,ROUND(D16,0),0) -> 0 | R16: =IF(R$3,ROUND(E16,0),0) -> 0 | S16: =IF(S$3,ROUND(F16,0),0) -> 0 | T16: =IF(T$3,ROUND(G16,0),0) -> 0 | U16: =IF(U$3,ROUND(H16,0),0) -> 0 | V16: =IF(V$3,ROUND(I16,0),0) -> 0 | W16: =IF(W$3,ROUND(J16,0),0) -> 0 | X16: =IF(X$3,ROUND(K16,0),0) -> 0 | Y16: =IF(Y$3,ROUND(L16,0),0) -> 0 | AA16: =IF(AA$3,ROUND(D16,0),0) -> 0 | AB16: =IF(AB$3,ROUND(E16,0),0) -> 0 | AC16: =IF(AC$3,ROUND(F16,0),0) -> 0 | AD16: =IF(AD$3,ROUND(G16,0),0) -> 0 | AE16: =IF(AE$3,ROUND(H16,0),0) -> 0 | AF16: =IF(AF$3,ROUND(I16,0),0) -> 0 | AG16: =IF(AG$3,ROUND(J16,0),0) -> 0 | AH16: =IF(AH$3,ROUND(K16,0),0) -> 0 | AI16: =IF(AI$3,ROUND(L16,0),0) -> 0 | AK16: =IF(AK$3,ROUND(D16,0),0) -> 0 | AL16: =IF(AL$3,ROUND(E16,0),0) -> 0 | AM16: =IF(AM$3,ROUND(F16,0),0) -> 0 | AN16: =IF(AN$3,ROUND(G16,0),0) -> 0 | AO16: =IF(AO$3,ROUND(H16,0),0) -> 0 | AP16: =IF(AP$3,ROUND(I16,0),0) -> 0 | AQ16: =IF(AQ$3,ROUND(J16,0),0) -> 0 | AR16: =IF(AR$3,ROUND(K16,0),0) -> 0 | AS16: =IF(AS$3,ROUND(L16,0),0) -> 0
B17: 12 | C17: FATCA filing requirement | M17: =" - - - -" -> - - - - | N17: =" - - - -" -> - - - - | O17: =" - - - -" -> - - - - | Q17: =IF(Q$3,ROUND(D17,0),0) -> 0 | R17: =IF(R$3,ROUND(E17,0),0) -> 0 | S17: =IF(S$3,ROUND(F17,0),0) -> 0 | T17: =IF(T$3,ROUND(G17,0),0) -> 0 | U17: =IF(U$3,ROUND(H17,0),0) -> 0 | V17: =IF(V$3,ROUND(I17,0),0) -> 0 | W17: =IF(W$3,ROUND(J17,0),0) -> 0 | X17: =IF(X$3,ROUND(K17,0),0) -> 0 | Y17: =IF(Y$3,ROUND(L17,0),0) -> 0 | AA17: =IF(AA$3,ROUND(D17,0),0) -> 0 | AB17: =IF(AB$3,ROUND(E17,0),0) -> 0 | AC17: =IF(AC$3,ROUND(F17,0),0) -> 0 | AD17: =IF(AD$3,ROUND(G17,0),0) -> 0 | AE17: =IF(AE$3,ROUND(H17,0),0) -> 0 | AF17: =IF(AF$3,ROUND(I17,0),0) -> 0 | AG17: =IF(AG$3,ROUND(J17,0),0) -> 0 | AH17: =IF(AH$3,ROUND(K17,0),0) -> 0 | AI17: =IF(AI$3,ROUND(L17,0),0) -> 0 | AK17: =IF(AK$3,ROUND(D17,0),0) -> 0 | AL17: =IF(AL$3,ROUND(E17,0),0) -> 0 | AM17: =IF(AM$3,ROUND(F17,0),0) -> 0 | AN17: =IF(AN$3,ROUND(G17,0),0) -> 0 | AO17: =IF(AO$3,ROUND(H17,0),0) -> 0 | AP17: =IF(AP$3,ROUND(I17,0),0) -> 0 | AQ17: =IF(AQ$3,ROUND(J17,0),0) -> 0 | AR17: =IF(AR$3,ROUND(K17,0),0) -> 0 | AS17: =IF(AS$3,ROUND(L17,0),0) -> 0
B18: 13 | C18: Date of Payment | M18: =" - - - -" -> - - - - | N18: =" - - - -" -> - - - - | O18: =" - - - -" -> - - - - | Q18: =IF(Q$3,ROUND(D18,0),0) -> 0 | R18: =IF(R$3,ROUND(E18,0),0) -> 0 | S18: =IF(S$3,ROUND(F18,0),0) -> 0 | T18: =IF(T$3,ROUND(G18,0),0) -> 0 | U18: =IF(U$3,ROUND(H18,0),0) -> 0 | V18: =IF(V$3,ROUND(I18,0),0) -> 0 | W18: =IF(W$3,ROUND(J18,0),0) -> 0 | X18: =IF(X$3,ROUND(K18,0),0) -> 0 | Y18: =IF(Y$3,ROUND(L18,0),0) -> 0 | AA18: =IF(AA$3,ROUND(D18,0),0) -> 0 | AB18: =IF(AB$3,ROUND(E18,0),0) -> 0 | AC18: =IF(AC$3,ROUND(F18,0),0) -> 0 | AD18: =IF(AD$3,ROUND(G18,0),0) -> 0 | AE18: =IF(AE$3,ROUND(H18,0),0) -> 0 | AF18: =IF(AF$3,ROUND(I18,0),0) -> 0 | AG18: =IF(AG$3,ROUND(J18,0),0) -> 0 | AH18: =IF(AH$3,ROUND(K18,0),0) -> 0 | AI18: =IF(AI$3,ROUND(L18,0),0) -> 0 | AK18: =IF(AK$3,ROUND(D18,0),0) -> 0 | AL18: =IF(AL$3,ROUND(E18,0),0) -> 0 | AM18: =IF(AM$3,ROUND(F18,0),0) -> 0 | AN18: =IF(AN$3,ROUND(G18,0),0) -> 0 | AO18: =IF(AO$3,ROUND(H18,0),0) -> 0 | AP18: =IF(AP$3,ROUND(I18,0),0) -> 0 | AQ18: =IF(AQ$3,ROUND(J18,0),0) -> 0 | AR18: =IF(AR$3,ROUND(K18,0),0) -> 0 | AS18: =IF(AS$3,ROUND(L18,0),0) -> 0
B19: 14 | C19: State tax withheld | M19: =SUM(Q19:Y19) -> 0 | N19: =SUM(AA19:AI19) -> 0 | O19: =SUM(AK19:AS19) -> 0 | Q19: =IF(Q$3,ROUND(D19,0),0) -> 0 | R19: =IF(R$3,ROUND(E19,0),0) -> 0 | S19: =IF(S$3,ROUND(F19,0),0) -> 0 | T19: =IF(T$3,ROUND(G19,0),0) -> 0 | U19: =IF(U$3,ROUND(H19,0),0) -> 0 | V19: =IF(V$3,ROUND(I19,0),0) -> 0 | W19: =IF(W$3,ROUND(J19,0),0) -> 0 | X19: =IF(X$3,ROUND(K19,0),0) -> 0 | Y19: =IF(Y$3,ROUND(L19,0),0) -> 0 | AA19: =IF(AA$3,ROUND(D19,0),0) -> 0 | AB19: =IF(AB$3,ROUND(E19,0),0) -> 0 | AC19: =IF(AC$3,ROUND(F19,0),0) -> 0 | AD19: =IF(AD$3,ROUND(G19,0),0) -> 0 | AE19: =IF(AE$3,ROUND(H19,0),0) -> 0 | AF19: =IF(AF$3,ROUND(I19,0),0) -> 0 | AG19: =IF(AG$3,ROUND(J19,0),0) -> 0 | AH19: =IF(AH$3,ROUND(K19,0),0) -> 0 | AI19: =IF(AI$3,ROUND(L19,0),0) -> 0 | AK19: =IF(AK$3,ROUND(D19,0),0) -> 0 | AL19: =IF(AL$3,ROUND(E19,0),0) -> 0 | AM19: =IF(AM$3,ROUND(F19,0),0) -> 0 | AN19: =IF(AN$3,ROUND(G19,0),0) -> 0 | AO19: =IF(AO$3,ROUND(H19,0),0) -> 0 | AP19: =IF(AP$3,ROUND(I19,0),0) -> 0 | AQ19: =IF(AQ$3,ROUND(J19,0),0) -> 0 | AR19: =IF(AR$3,ROUND(K19,0),0) -> 0 | AS19: =IF(AS$3,ROUND(L19,0),0) -> 0
B20: 15 | C20: State/payer's state no. | M20: =" - - - -" -> - - - - | N20: =" - - - -" -> - - - - | O20: =" - - - -" -> - - - -
B21: 16 | C21: State distribution | M21: =SUM(Q21:Y21) -> 0 | N21: =SUM(AA21:AI21) -> 0 | O21: =SUM(AK21:AS21) -> 0 | Q21: =IF(Q$3,ROUND(D21,0),0) -> 0 | R21: =IF(R$3,ROUND(E21,0),0) -> 0 | S21: =IF(S$3,ROUND(F21,0),0) -> 0 | T21: =IF(T$3,ROUND(G21,0),0) -> 0 | U21: =IF(U$3,ROUND(H21,0),0) -> 0 | V21: =IF(V$3,ROUND(I21,0),0) -> 0 | W21: =IF(W$3,ROUND(J21,0),0) -> 0 | X21: =IF(X$3,ROUND(K21,0),0) -> 0 | Y21: =IF(Y$3,ROUND(L21,0),0) -> 0 | AA21: =IF(AA$3,ROUND(D21,0),0) -> 0 | AB21: =IF(AB$3,ROUND(E21,0),0) -> 0 | AC21: =IF(AC$3,ROUND(F21,0),0) -> 0 | AD21: =IF(AD$3,ROUND(G21,0),0) -> 0 | AE21: =IF(AE$3,ROUND(H21,0),0) -> 0 | AF21: =IF(AF$3,ROUND(I21,0),0) -> 0 | AG21: =IF(AG$3,ROUND(J21,0),0) -> 0 | AH21: =IF(AH$3,ROUND(K21,0),0) -> 0 | AI21: =IF(AI$3,ROUND(L21,0),0) -> 0 | AK21: =IF(AK$3,ROUND(D21,0),0) -> 0 | AL21: =IF(AL$3,ROUND(E21,0),0) -> 0 | AM21: =IF(AM$3,ROUND(F21,0),0) -> 0 | AN21: =IF(AN$3,ROUND(G21,0),0) -> 0 | AO21: =IF(AO$3,ROUND(H21,0),0) -> 0 | AP21: =IF(AP$3,ROUND(I21,0),0) -> 0 | AQ21: =IF(AQ$3,ROUND(J21,0),0) -> 0 | AR21: =IF(AR$3,ROUND(K21,0),0) -> 0 | AS21: =IF(AS$3,ROUND(L21,0),0) -> 0
